<?xml version="1.0"?>
<!-- Revolute-Revolute Manipulator -->
<robot name="kejia" xmlns:xacro="http://www.ros.org/wiki/xacro">

  <!-- Constants for robot dimensions -->
  <xacro:property name="PI" value="3.1415926535897931"/>
  <xacro:property name="mass" value="1" /> <!-- arbitrary value for mass -->
  <xacro:property name="base_length" value=".4" />
  <xacro:property name="base_width" value=".2" />
  <xacro:property name="base_height" value=".1" />

  <xacro:property name="caster_radius" value="0.05" />
  <xacro:property name="mass" value="1" />

  <xacro:property name="wheel_radius" value="2" /> <!-- Link 1 -->

  <!-- Import all Gazebo-customization elements, including Gazebo colors -->
  <xacro:include filename="$(find kejia_description)/urdf/kejia.gazebo" />
  <!-- Import Rviz colors -->
  <xacro:include filename="$(find kejia_description)/urdf/materials.xacro" />

  <!-- Used for fixing robot to Gazebo 'base_link' -->
  <link name="world"/>

  <joint name="fixed" type="floating">
    <parent link="world"/>
    <child link="base_link"/>
  </joint>

  <!-- Base Link -->
  <link name="base_link">
    <collision>
      <origin xyz="0 0 .1" rpy="0 0 0"/>
      <geometry>
        <box size="${base_length} ${base_width} ${base_height}"/>
      </geometry>
    </collision>

    <visual name='visual'>
      <origin xyz="0 0 .1" rpy="0 0 0"/>
      <geometry>
        <box size="${base_length} ${base_width} ${base_height}"/>
      </geometry>
      <material name="grey"/>
    </visual>

    <!--TODO-->
    <inertial>
      <origin xyz="0 0 .1" rpy="0 0 0"/>
      <mass value="${mass}"/>
      <inertia
      ixx="1" ixy="0.0" ixz="0.0"
      iyy="1" iyz="0.0"
      izz="1"/>
    </inertial>

    <collision>
      <origin xyz="-0.5 0 0.05" rpy="0 0 0"/>
      <geometry>
        <sphere radius=".05"/>
      </geometry>
    </collision>

    <visual>
      <origin xyz="-0.15 0 0.05" rpy="0 0 0"/>
      <geometry>
        <sphere radius=".05"/>
      </geometry>
      <material name="grey"/>
    </visual>

  </link>

  <!-- Left Wheel -->
  <link name="left_wheel">
    <collision>
      <origin xyz="0 0 0" rpy="0 1.5707 1.5707"/>
      <geometry>
        <cylinder length=".05" radius=".1"/>
      </geometry>
    </collision>
    <visual>
      <origin xyz="0 0 0" rpy="0 1.5707 1.5707"/>
      <geometry>
        <cylinder length=".05" radius=".1"/>
      </geometry>
      <material name="grey"/>
    </visual>
    <inertial>
      <origin xyz="0 0 0" rpy="0 1.5707 1.5707"/>
      <mass value="${mass}"/>
      <inertia
      ixx="1" ixy="0.0" ixz="0.0"
      iyy="1" iyz="0.0"
      izz="1"/>
    </inertial>
  </link>
  <!-- Right Wheel -->
  <link name="right_wheel">
    <collision>
      <origin xyz="0 0 0" rpy="0 1.5707 1.5707"/>
      <geometry>
        <cylinder length=".05" radius=".1"/>
      </geometry>
    </collision>

    <visual>
      <origin xyz="0 0 0" rpy="0 1.5707 1.5707"/>
      <geometry>
        <cylinder length=".05" radius=".1"/>
      </geometry>
      <material name="grey"/>
    </visual>

    <inertial>
      <origin xyz="0 0 0" rpy="0 1.5707 1.5707"/>
      <mass value="${mass}"/>
      <inertia
      ixx="1" ixy="0.0" ixz="0.0"
      iyy="1" iyz="0.0"
      izz="1"/>
    </inertial>
  </link>

  <joint name="joint1" type="continuous">
    <parent link="base_link"/>
    <child link="left_wheel"/>
    <origin xyz="0.1 0.13 0.1" rpy="0 0 0"/>
    <axis xyz="0 1 0"/>
  </joint>

  <joint name="joint2" type="continuous">
    <origin xyz="0.1 -0.13 0.1" rpy="0 0 0"/>
    <parent link="base_link"/>
    <child link="right_wheel"/>
    <axis xyz="0 1 0"/>
  </joint>

  <!-- Hokuyo Laser -->
  <link name="hokuyo_link">
    <collision>
      <origin xyz="0 0 0" rpy="0 0 0"/>
      <geometry>
	      <box size="0.1 0.1 0.1"/>
      </geometry>
    </collision>

    <visual>
      <origin xyz="0 0 0" rpy="0 0 0"/>
      <geometry>
        <mesh filename="package://kejia_description/meshes/hokuyo.dae"/>
      </geometry>
    </visual>

    <inertial>
      <mass value="1e-5" />
      <origin xyz="0 0 0" rpy="0 0 0"/>
      <inertia ixx="1e-6" ixy="0" ixz="0" iyy="1e-6" iyz="0" izz="1e-6" />
    </inertial>

  </link>

  <joint name="hokuyo_joint" type="fixed">
    <axis xyz="0 1 0" />
    <origin xyz="0.15 0 0.2" rpy="0 0 0"/>
    <parent link="base_link"/>
    <child link="hokuyo_link"/>
  </joint>

  <transmission name="tran1">
    <type>transmission_interface/SimpleTransmission</type>
    <joint name="joint1">
      <hardwareInterface>EffortJointInterface</hardwareInterface>
    </joint>
    <actuator name="motor1">
      <hardwareInterface>EffortJointInterface</hardwareInterface>
      <mechanicalReduction>1</mechanicalReduction>
    </actuator>
  </transmission>

  <transmission name="tran2">
    <type>transmission_interface/SimpleTransmission</type>
    <joint name="joint2">
      <hardwareInterface>EffortJointInterface</hardwareInterface>
    </joint>
    <actuator name="motor2">
      <hardwareInterface>EffortJointInterface</hardwareInterface>
      <mechanicalReduction>1</mechanicalReduction>
    </actuator>
  </transmission>

</robot>
