<?xml version="1.0" ?>
<sdf version="1.5">
  <model name="kejia">
    <!--laser_link-->
    <link name="laser_link">
      <pose>0.2 0 0.35 0 0 0</pose>
      <gravity>false</gravity>
      <visual name="visual">
        <geometry>
          <mesh>
            <uri>file://hokuyo.dae</uri>
          </mesh>
        </geometry>
      </visual>
      <sensor type="ray" name="head_hokuyo_sensor">
        <pose>0 0 0 0 0 0</pose>
        <visualize>true</visualize>
        <update_rate>40</update_rate>
        <ray>
          <scan>
            <horizontal>
              <samples>800</samples>
              <resolution>1</resolution>
              <min_angle>-2</min_angle>
              <max_angle>2</max_angle>
            </horizontal>
          </scan>
          <range>
            <min>0.10</min>
            <max>30.0</max>
            <resolution>0.01</resolution>
          </range>
        <!-- <noise-->
            <!--type>gaussian</type-->
            <!-- Noise parameters based on published spec for Hokuyo laser
                achieving "+-30mm" accuracy at range < 10m.  A mean of 0.0m and
                stddev of 0.01m will put 99.7% of samples within 0.03m of the true
                reading. -->
            <!--mean>0.0</mean-->
            <!--stddev>0.01</stddev-->
          <!--/noise-->
        </ray>
        <plugin name="gazebo_ros_head_hokuyo_controller" filename="libgazebo_ros_laser.so">
          <topicName>/scan</topicName>
          <frameName>laser_link</frameName>
        </plugin>
      </sensor>
    </link>
    <!--base_link-->
    <link name="base_link">
	    <sensor name='my_contact' type='contact'>
        <plugin name="gazebo_ros_bumper" filename="libgazebo_ros_bumper.so">
          <alwaysOn>true</alwaysOn>
          <updateRate>5</updateRate>
          <bumperTopicName>bumper</bumperTopicName>
          <frameName>base_link</frameName>
        </plugin>
        <contact>
          <collision>collision</collision>
        </contact>
      </sensor>
      <pose>0 0 0.16 0 0 0</pose>
      <inertial>
        <mass>5</mass>
        <inertia>
          <ixx>0.13</ixx>
          <iyy>0.152</iyy>
          <izz>0.23</izz>
          <ixy>0</ixy>
          <ixz>0</ixz>
          <iyz>0</iyz>
        </inertia>
      </inertial>
      <collision name="collision">
        <geometry>
          <box>
            <size>0.55 0.5 0.25</size>
          </box>
        </geometry>
      </collision>
      <visual name="visual">
        <pose>0 0 0.04 0 0 0</pose>
        <geometry>
          <box>
            <size>0.55 0.5 0.25</size>
          </box>
        </geometry>
      </visual>
    </link>
    <!--ev_link-->
    <link name="ev_link">
      <gravity>false</gravity>
      <sensor name='ev_contact' type='contact'>
        <plugin name="gazebo_ros_bumper" filename="libgazebo_ros_bumper.so">
          <alwaysOn>true</alwaysOn>
          <updateRate>5</updateRate>
          <bumperTopicName>bumper</bumperTopicName>
          <frameName>ev_link</frameName>
        </plugin>
        <contact>
          <collision>collision</collision>
        </contact>
      </sensor>
      <pose>-0.1 0 0.7 0 0 0</pose>
      <collision name="collision">
        <geometry>
          <box>
            <size>0.1 0.1 0.8</size>
          </box>
        </geometry>
      </collision>
      <visual name="visual">
        <pose>0 0 0 0 0 0</pose>
        <geometry>
          <box>
            <size>0.1 0.1 0.8</size>
          </box>
        </geometry>
      </visual>
    </link>
    <link name="kinect_link">
      <gravity>false</gravity>
      <pose>-0.05 0 1.15 0 0 0</pose>
      <collision name="collision">
        <geometry>
          <box>
            <size>0.073000 0.276000 0.072000</size>
          </box>
        </geometry>
      </collision>
      <visual name="visual">
        <geometry>
          <mesh>
            <uri>model://kejia/meshes/kinect.dae</uri>
          </mesh>
        </geometry>
      </visual>
      <sensor name="camera" type="depth">
        <update_rate>20</update_rate>
        <camera>
          <horizontal_fov>1.047198</horizontal_fov>
          <image>
            <width>640</width>
            <height>480</height>
            <format>R8G8B8</format>
          </image>
          <clip>
            <near>0.05</near>
            <far>3</far>
          </clip>
        </camera>
        <plugin name="camera_controller" filename="libgazebo_ros_openni_kinect.so">
            <alwaysOn>true</alwaysOn>
            <updateRate>10.0</updateRate>
            <cameraName>kinect</cameraName>
            <frameName>kinect_link</frameName>                   
            <imageTopicName>rgb/image_raw</imageTopicName>
            <depthImageTopicName>depth/image_raw</depthImageTopicName>
            <pointCloudTopicName>depth/points</pointCloudTopicName>
            <cameraInfoTopicName>rgb/camera_info</cameraInfoTopicName>              
            <depthImageCameraInfoTopicName>depth/camera_info</depthImageCameraInfoTopicName>            
            <pointCloudCutoff>0.4</pointCloudCutoff>                
            <hackBaseline>0.07</hackBaseline>
            <distortionK1>0.0</distortionK1>
            <distortionK2>0.0</distortionK2>
            <distortionK3>0.0</distortionK3>
            <distortionT1>0.0</distortionT1>
            <distortionT2>0.0</distortionT2>
            <CxPrime>0.0</CxPrime>
            <Cx>0.0</Cx>
            <Cy>0.0</Cy>
            <focalLength>0.0</focalLength>
        </plugin>
      </sensor>
    </link>
    <link name="back_wheel">
      <pose>-0.2 0 0.04 0 1.5707 1.5707</pose>
      <inertial>
        <mass>10</mass>
        <inertia>
          <ixx>0.0032</ixx>
          <iyy>0.0032</iyy>
          <izz>0.001</izz>
          <ixy>0</ixy>
          <ixz>0</ixz>
          <iyz>0</iyz>
        </inertia>
      </inertial>
      <visual name="castor_visual">
        <geometry>
          <sphere>
            <radius>0.04</radius>
          </sphere>
        </geometry>
        <material>
          <script>
            <uri>file://media/materials/scripts/gazebo.material</uri>
            <name>Gazebo/FlatBlack</name>
          </script>
        </material>
      </visual>
      <collision name="castor_collision">
        <geometry>
          <sphere>
            <radius>0.04</radius>
          </sphere>
        </geometry>
        <surface>
          <friction>
            <ode>
              <mu>0</mu>
              <mu2>0</mu2>
              <slip1>0.0</slip1>
              <slip2>0.0</slip2>
            </ode>
          </friction>
        </surface>
      </collision>
    </link>
    <!--right_wheel-->
    <link name="right_wheel">
      <pose>0.1 -.17 0.11 0 1.5707 1.5707</pose>
      <inertial>
        <mass>10</mass>
        <inertia>
          <ixx>0.0032</ixx>
          <iyy>0.0032</iyy>
          <izz>0.001</izz>
          <ixy>0</ixy>
          <ixz>0</ixz>
          <iyz>0</iyz>
        </inertia>
      </inertial>
      <collision name="right_collision">
        <geometry>
          <cylinder>
            <radius>0.11</radius>
            <length>0.05</length>
          </cylinder>
        </geometry>
        <surface>
          <friction>
            <ode>
              <mu>100000.0</mu>
              <mu2>100000.0</mu2>
              <slip1>0.0</slip1>
              <slip2>0.0</slip2>
            </ode>
          </friction>
        </surface>
      </collision>
      <visual name="visual">
        <geometry>
          <cylinder>
            <radius>0.11</radius>
            <length>0.05</length>
          </cylinder>
        </geometry>
        <material>
          <script>
            <uri>file://media/materials/scripts/gazebo.material</uri>
            <name>Gazebo/FlatBlack</name>
          </script>
        </material>
      </visual>
    </link>
    <!--left_wheel-->
    <link name="left_wheel">
      <pose>0.1 .17 0.11 0 1.5707 1.5707</pose>
      <inertial>
        <mass>10</mass>
        <inertia>
          <ixx>0.0032</ixx>
          <iyy>0.0032</iyy>
          <izz>0.001</izz>
          <ixy>0</ixy>
          <ixz>0</ixz>
          <iyz>0</iyz>
        </inertia>
      </inertial>
      <collision name="left_collision">
        <geometry>
          <cylinder>
            <radius>0.11</radius>
            <length>0.05</length>
          </cylinder>
        </geometry>
        <surface>
          <friction>
            <ode>
              <mu>100000.0</mu>
              <mu2>100000.0</mu2>
              <slip1>0.0</slip1>
              <slip2>0.0</slip2>
            </ode>
          </friction>
        </surface>
      </collision>
      <visual name="visual">
        <geometry>
          <cylinder>
            <radius>0.11</radius>
            <length>0.05</length>
          </cylinder>
        </geometry>
        <material>
          <script>
            <uri>file://media/materials/scripts/gazebo.material</uri>
            <name>Gazebo/FlatBlack</name>
          </script>
        </material>
      </visual>
    </link>
    <!--left_wheel_joint-->
    <joint type="revolute" name="left_wheel_hinge">
      <pose>0 0 0 0 0 0</pose>
      <child>left_wheel</child>
      <parent>base_link</parent>
      <axis>
        <xyz>0 0 1</xyz>
      </axis>
    </joint>
    <!--right_wheel_joint-->
    <joint type="revolute" name="right_wheel_hinge">
      <pose>0 0 0 0 0 0</pose>
      <child>right_wheel</child>
      <parent>base_link</parent>
      <axis>
        <xyz>0 0 1</xyz>
      </axis>
    </joint>
    <joint type="revolute" name="back_wheel_hinge">
      <pose>0 0 0 0 0 0</pose>
      <child>back_wheel</child>
      <parent>base_link</parent>
      <axis>
        <xyz>0 0 1</xyz>
      </axis>
    </joint>
    <!--laser_joint-->
    <joint name="hokuyo_joint" type="fixed">
      <child>laser_link</child>
      <parent>base_link</parent>
    </joint>
    <!--ev_base_joint-->
    <joint name="ev_base_joint" type="fixed">
      <child>ev_link</child>
      <parent>base_link</parent>
    </joint>
    <!--ev_base_joint-->
    <joint name="ev_kinect_joint" type="fixed">
      <child>ev_link</child>
      <parent>kinect_link</parent>
    </joint>
    <plugin name="differential_drive_controller" filename="libgazebo_ros_diff_drive.so">
      <alwaysOn>true</alwaysOn>
      <updateRate>40</updateRate>
      <leftJoint>left_wheel_hinge</leftJoint>
      <rightJoint>right_wheel_hinge</rightJoint>
      <wheelSeparation>0.34</wheelSeparation>
      <wheelDiameter>0.22</wheelDiameter>
      <torque>10</torque>
      <commandTopic>/cmd_vel</commandTopic>
      <odometryTopic>/odom</odometryTopic>
      <odometryFrame>/odom</odometryFrame>
      <odometryRate>30.0</odometryRate>
      <robotBaseFrame>/base_link</robotBaseFrame>
      <legacyMode>false</legacyMode>
    </plugin>
  </model>
</sdf>
